<?xml version="1.0" ?>
<!-- =================================================================================== -->
<!-- |    This document was autogenerated by xacro from kinton_arm.xacro               | -->
<!-- |    EDITING THIS FILE BY HAND IS NOT RECOMMENDED                                 | -->
<!-- =================================================================================== -->
<robot name="kinton" xmlns:xacro="http://ros.org/wiki/xacro">
  <!--  Be sure the parameter server has the correct chain joints 
        <param name="root_name" value="base_link" />  
        <param name="tip_name" value="arm_joint6" />  -->
  <material name="black">
    <color rgba="0.15 0.15 0.15 1.0"/>
  </material>
  <material name="blue">
    <color rgba="0.17 0.3 0.56 1.0"/>
  </material>
  <material name="orange">
    <color rgba="0.93 0.44 0.01 1.0"/>
  </material>
  <material name="green">
    <color rgba="0.0 0.8 0.0 1.0"/>
  </material>
  <material name="grey">
    <color rgba="0.3 0.3 0.3 1.0"/>
  </material>
  <material name="grey2">
    <color rgba="0.7 0.7 0.7 1.0"/>
  </material>
  <material name="grey3">
    <color rgba="0.9 0.9 0.9 1.0"/>
  </material>
  <material name="red">
    <color rgba="0.8 0.0 0.0 1.0"/>
  </material>
  <material name="white">
    <color rgba="0.9 0.9 0.9 1.0"/>
  </material>
  <link name="base_link">
    <inertial>
      <mass value="1.477"/>
      <origin xyz="0 0 0"/>
      <inertia ixx="0.01152" ixy="0.0" ixz="0.0" iyy="0.01152" iyz="0.0" izz="0.0218"/>
    </inertial>
    <visual>
      <origin rpy="0.0 0.0 0.0" xyz="0.0 0.0 0.0"/>
      <geometry>
        <mesh filename="package://kinton_description/meshes/kinton/kinton2.dae" scale="1 1 1"/>
      </geometry>
      <material name="grey"/>
    </visual>
    <collision>
      <origin rpy="0.0 0.0 0.0" xyz="0.0 0.0 0.0"/>
      <geometry>
        <mesh filename="package://kinton_description/meshes/kinton/kinton2.stl" scale="1 1 1"/>
      </geometry>
    </collision>
  </link>
  <!-- Base footprint -->
  <!--   <link name="base_footprint">
    <inertial>
      <mass value="0.01" />
      <origin xyz="0 0 -0.195" rpy="0 0 0"/>
      <inertia ixx="0.001"  ixy="0.0"  ixz="0.0" iyy="0.001"  iyz="0.0" izz="0.001" />
    </inertial>
    <visual>
      <origin xyz="0 0 0" rpy="0 0 0"/>
      <geometry>
        <box size="0.00001 0.00001 0.00001" />
      </geometry>
      <material name="grey"/>
    </visual>
  </link>
  <joint name="base_link_to_base_footprint" type="fixed">
    <parent link="base_link"/>
    <child link="base_footprint"/>
    <origin xyz="0.00 0.00 -0.195" rpy="0.0 0.0 0.0"/>
  </joint>   -->
  <!-- COMPASS -->
  <link name="compass">
    <inertial>
      <mass value="0.01"/>
      <origin rpy="0.0 0.0 2.35619449019" xyz="0.0 0.0 0.0"/>
      <inertia ixx="0.001" ixy="0.0" ixz="0.0" iyy="0.001" iyz="0.0" izz="0.001"/>
    </inertial>
    <visual>
      <geometry>
        <box size="0.02 0.02 0.01"/>
      </geometry>
      <origin rpy="0.0 0.0 2.35619449019" xyz="0.0 0.0 0.0"/>
      <material name="grey"/>
    </visual>
    <collision>
      <origin rpy="0.0 0.0 2.35619449019" xyz="0.0 0.0 0.0"/>
      <geometry>
        <box size="0.02 0.02 0.01"/>
      </geometry>
    </collision>
  </link>
  <joint name="base_link_to_compass" type="fixed">
    <parent link="base_link"/>
    <child link="compass"/>
    <origin rpy="0.0 0.0 -2.35619449019" xyz="-0.015 0.0 0.066"/>
  </joint>
  <gazebo>
    <plugin filename="libhector_gazebo_ros_magnetic.so" name="magnetic_sim">
      <alwaysOn>true</alwaysOn>
      <updateRate>10.0</updateRate>
      <bodyName>base_link</bodyName>
      <topicName>kinton/magnetic</topicName>
      <offset>0 0 0</offset>
      <drift>0.0 0.0 0.0</drift>
      <driftFrequency>0.0 0.0 0.0</driftFrequency>
      <gaussianNoise>1.3e-2 1.3e-2 1.3e-2</gaussianNoise>
    </plugin>
  </gazebo>
  <gazebo reference="compass">
    <material>Gazebo/Black</material>
    <turnGravityOff>true</turnGravityOff>
  </gazebo>
  <!-- GYROS -->
  <link name="imu">
    <inertial>
      <mass value="0.01"/>
      <origin rpy="0.0 0.0 2.35619449019" xyz="0.0 0.0 0.0"/>
      <inertia ixx="0.001" ixy="0.0" ixz="0.0" iyy="0.001" iyz="0.0" izz="0.001"/>
    </inertial>
    <visual>
      <geometry>
        <box size="0.03 0.03 0.005"/>
      </geometry>
      <origin rpy="0.0 0.0 2.35619449019" xyz="0.0 0.0 0.0"/>
      <material name="grey"/>
    </visual>
    <collision>
      <origin rpy="0.0 0.0 2.35619449019" xyz="0.0 0.0 0.0"/>
      <geometry>
        <box size="0.03 0.03 0.005"/>
      </geometry>
    </collision>
  </link>
  <joint name="base_link_to_imu" type="fixed">
    <parent link="base_link"/>
    <child link="imu"/>
    <origin rpy="0.0 0.0 0.785398163397" xyz="0.0 0.0 0.04"/>
  </joint>
  <gazebo>
    <plugin filename="libhector_gazebo_ros_imu.so" name="imu_sim">
      <alwaysOn>true</alwaysOn>
      <updateRate>100.0</updateRate>
      <bodyName>base_link</bodyName>
      <frameId>kinton/imu</frameId>
      <topicName>kinton/imu_raw</topicName>
      <rpyOffsets>0 0 0</rpyOffsets>
      <!-- deprecated -->
      <gaussianNoise>0</gaussianNoise>
      <!-- deprecated -->
      <accelDrift>0.5 0.5 0.5</accelDrift>
      <accelOffset>0.0 0.0 0.0</accelOffset>
      <accelDriftFrequency>0.0 0.0 0.0</accelDriftFrequency>
      <accelGaussianNoise>0.35 0.35 0.3</accelGaussianNoise>
      <rateDrift>0.0 0.0 0.0</rateDrift>
      <rateOffset>0.0 0.0 0.0</rateOffset>
      <rateDriftFrequency>0.0 0.0 0.0</rateDriftFrequency>
      <rateGaussianNoise>0.00 0.00 0.00</rateGaussianNoise>
      <headingDrift>0.0</headingDrift>
      <headingGaussianNoise>0.00</headingGaussianNoise>
      <headingOffset>0.0</headingOffset>
      <headingDriftFrequency>0.0</headingDriftFrequency>
    </plugin>
  </gazebo>
  <gazebo reference="imu">
    <material>Gazebo/Black</material>
    <turnGravityOff>true</turnGravityOff>
  </gazebo>
  <gazebo>
    <plugin filename="libgazebo_ros_p3d.so" name="odom_sim">
      <alwaysOn>true</alwaysOn>
      <updateRate>100.0</updateRate>
      <bodyName>base_link</bodyName>
      <topicName>kinton/odom</topicName>
      <gaussianNoise>0.0</gaussianNoise>
      <frameName>world</frameName>
    </plugin>
  </gazebo>
  <!-- GPS -->
  <link name="gps">
    <inertial>
      <mass value="0.01"/>
      <origin rpy="0.0 0.0 0.0" xyz="0.0 0.0 0.0"/>
      <inertia ixx="0.001" ixy="0.0" ixz="0.0" iyy="0.001" iyz="0.0" izz="0.001"/>
    </inertial>
    <visual>
      <geometry>
        <box size="0.02 0.04 0.02"/>
      </geometry>
      <origin rpy="0.0 0.0 0.0" xyz="0.0 0.0 0.0"/>
      <material name="grey"/>
    </visual>
    <collision>
      <origin rpy="0.0 0.0 0.0" xyz="0.0 0.0 0.0"/>
      <geometry>
        <box size="0.02 0.04 0.02"/>
      </geometry>
    </collision>
  </link>
  <joint name="base_link_to_gps" type="fixed">
    <parent link="base_link"/>
    <child link="gps"/>
    <origin rpy="0.0 0.0 0.0" xyz="0.02 0.0 0.066"/>
  </joint>
  <gazebo>
    <plugin filename="libhector_gazebo_ros_gps.so" name="gps_sim">
      <alwaysOn>true</alwaysOn>
      <updateRate>5.0</updateRate>
      <bodyName>base_link</bodyName>
      <topicName>kinton/fix</topicName>
      <velocityTopicName>kinton/fix_velocity</velocityTopicName>
      <referenceLatitude>41.3851</referenceLatitude>
      <referenceLongitude>2.1734</referenceLongitude>
      <referenceAltitude>5.0</referenceAltitude>
      <referenceHeading>0.0</referenceHeading>
      <!--TEST 90 for testing with robot_pose_ekf -->
      <offset>0 0 0</offset>
      <drift>5.0 5.0 5.0</drift>
      <driftFrequency>0.0 0.0 0.0</driftFrequency>
      <gaussianNoise>0.1 0.1 0.1</gaussianNoise>
      <velocityOffset>0 0 0</velocityOffset>
      <velocityDrift>0 0 0</velocityDrift>
      <velocityDriftFrequency>0 0 0</velocityDriftFrequency>
      <velocityGaussianNoise>0.1 0.1 0.1</velocityGaussianNoise>
    </plugin>
  </gazebo>
  <gazebo reference="gps">
    <material>Gazebo/Black</material>
    <turnGravityOff>true</turnGravityOff>
  </gazebo>
  <!-- WITHOUT ARM -->
  <!-- <gazebo>
      <plugin name="quadrotor_simple_controller" filename="libkinton_gazebo.so">
        <alwaysOn>true</alwaysOn>
        <updateRate>0.0</updateRate>
        <bodyName>base_link</bodyName>
        <stateTopic>${prefix}/odom</stateTopic>
        <imuTopic>${prefix}/imu_raw</imuTopic>
        <cmdvelTopic>${prefix}/cmd_vel</cmdvelTopic>
        <mavctrlTopic>fcu/control</mavctrlTopic>
        <rollpitchProportionalGain>10.0</rollpitchProportionalGain>
        <rollpitchDifferentialGain>5.0</rollpitchDifferentialGain>
        <rollpitchLimit>0.5</rollpitchLimit>
        <yawProportionalGain>2.0</yawProportionalGain>
        <yawDifferentialGain>1.0</yawDifferentialGain>
        <yawLimit>1.0</yawLimit>
        <velocityXYProportionalGain>5.0</velocityXYProportionalGain>
        <velocityXYDifferentialGain>1.0</velocityXYDifferentialGain>
        <velocityXYLimit>1.0</velocityXYLimit>
        <velocityZProportionalGain>50.0</velocityZProportionalGain>
        <velocityZDifferentialGain>1.1</velocityZDifferentialGain>
        <velocityZLimit>1.0</velocityZLimit>
        <maxForce>30</maxForce>
        <motionSmallNoise>0.05</motionSmallNoise>
        <motionDriftNoise>0.03</motionDriftNoise>
        <motionDriftNoiseTime>5.0</motionDriftNoiseTime>
      </plugin>
    </gazebo> -->
  <!-- WITH ARM >> NOT TUNNED -->
  <gazebo>
    <plugin filename="libkinton_gazebo.so" name="quadrotor_simple_controller">
      <alwaysOn>true</alwaysOn>
      <updateRate>0.0</updateRate>
      <bodyName>base_link</bodyName>
      <stateTopic>kinton/odom</stateTopic>
      <imuTopic>kinton/imu_raw</imuTopic>
      <cmdvelTopic>kinton/cmd_vel</cmdvelTopic>
      <mavctrlTopic>fcu/control</mavctrlTopic>
      <rollpitchProportionalGain>10.0</rollpitchProportionalGain>
      <rollpitchDifferentialGain>5.0</rollpitchDifferentialGain>
      <rollpitchLimit>0.5</rollpitchLimit>
      <yawProportionalGain>2.0</yawProportionalGain>
      <yawDifferentialGain>1.0</yawDifferentialGain>
      <yawLimit>1.0</yawLimit>
      <velocityXYProportionalGain>5.0</velocityXYProportionalGain>
      <velocityXYDifferentialGain>1.0</velocityXYDifferentialGain>
      <velocityXYLimit>1.0</velocityXYLimit>
      <velocityZProportionalGain>50.0</velocityZProportionalGain>
      <velocityZDifferentialGain>1.1</velocityZDifferentialGain>
      <velocityZLimit>1.0</velocityZLimit>
      <maxForce>30</maxForce>
      <motionSmallNoise>0.05</motionSmallNoise>
      <motionDriftNoise>0.03</motionDriftNoise>
      <motionDriftNoiseTime>5.0</motionDriftNoiseTime>
    </plugin>
  </gazebo>
  <!-- Kinton-Arm joint -->
  <joint name="fixed" type="fixed">
    <parent link="base_link"/>
    <child link="arm_base"/>
    <origin rpy="0 0 0" xyz="0 0 -0.09"/>
  </joint>
  <!-- Arm Base -->
  <link name="arm_base">
    <collision>
      <origin rpy="0 0 0" xyz="0 0 0.0"/>
      <geometry>
        <mesh filename="package://kinton_description/meshes/arm/base.stl"/>
      </geometry>
      <contact_coefficients kd="1.0" kp="1000.0" mu="0"/>
    </collision>
    <visual>
      <origin rpy="0 0 0" xyz="0 0 0.0"/>
      <geometry>
        <mesh filename="package://kinton_description/meshes/arm/base.dae"/>
      </geometry>
      <material name="white"/>
    </visual>
    <inertial>
      <origin rpy="0 0 0" xyz="0 0 0.0"/>
      <mass value="0.0002"/>
      <inertia ixx="0.01" ixy="0.0" ixz="0.0" iyy="0.01" iyz="0.0" izz="0.01"/>
    </inertial>
  </link>
  <joint name="joint1" type="revolute">
    <parent link="arm_base"/>
    <child link="link1"/>
    <origin rpy="3.14159265359 0 3.14159265359" xyz="0.0 0.0 0.0"/>
    <axis xyz="0 0 1"/>
    <limit effort="1.0" lower="-0.35" upper="0.35" velocity="1.0"/>
    <dynamics damping="1.0"/>
  </joint>
  <transmission name="tran1">
    <type>transmission_interface/SimpleTransmission</type>
    <joint name="joint1">
      <hardwareInterface>hardware_interface/EffortJointInterface</hardwareInterface>
    </joint>
    <actuator name="motor1">
      <hardwareInterface>hardware_interface/EffortJointInterface</hardwareInterface>
      <mechanicalReduction>1</mechanicalReduction>
    </actuator>
  </transmission>
  <!-- Link1 -->
  <link name="link1">
    <collision>
      <origin rpy="0 0 0" xyz="0 0 0"/>
      <geometry>
        <mesh filename="package://kinton_description/meshes/arm/link1.stl"/>
      </geometry>
      <contact_coefficients kd="1.0" kp="1000.0" mu="0"/>
    </collision>
    <visual>
      <origin rpy="0 0 0" xyz="0 0 0"/>
      <geometry>
        <mesh filename="package://kinton_description/meshes/arm/link1.dae"/>
      </geometry>
      <material name="white"/>
    </visual>
    <inertial>
      <origin rpy="0 0 0" xyz="0 0 0"/>
      <mass value="0.0002"/>
      <inertia ixx="0.01" ixy="0.0" ixz="0.0" iyy="0.01" iyz="0.0" izz="0.01"/>
    </inertial>
  </link>
  <joint name="joint2" type="revolute">
    <parent link="link1"/>
    <child link="link2"/>
    <origin rpy="-1.57079632679 0 -1.57079632679" xyz="0 0 0.038"/>
    <axis xyz="0 0 1"/>
    <limit effort="1.0" lower="-0.523" upper="0.523" velocity="1.0"/>
    <dynamics damping="1.0"/>
  </joint>
  <transmission name="tran2">
    <type>transmission_interface/SimpleTransmission</type>
    <joint name="joint2">
      <hardwareInterface>hardware_interface/EffortJointInterface</hardwareInterface>
    </joint>
    <actuator name="motor2">
      <hardwareInterface>hardware_interface/EffortJointInterface</hardwareInterface>
      <mechanicalReduction>1</mechanicalReduction>
    </actuator>
  </transmission>
  <!-- Link2 -->
  <link name="link2">
    <collision>
      <origin rpy="0 0 0" xyz="0 0 0"/>
      <geometry>
        <mesh filename="package://kinton_description/meshes/arm/link2.stl"/>
      </geometry>
      <contact_coefficients kd="1.0" kp="1000.0" mu="0"/>
    </collision>
    <visual>
      <origin rpy="0 0 0" xyz="0 0 0"/>
      <geometry>
        <mesh filename="package://kinton_description/meshes/arm/link2.dae"/>
      </geometry>
      <material name="white"/>
    </visual>
    <inertial>
      <origin rpy="0 0 0" xyz="0 0 0"/>
      <mass value="0.0002"/>
      <inertia ixx="0.01" ixy="0.0" ixz="0.0" iyy="0.01" iyz="0.0" izz="0.01"/>
    </inertial>
  </link>
  <joint name="joint3" type="revolute">
    <parent link="link2"/>
    <child link="link3"/>
    <origin rpy="-1.57079632679 0 -1.57079632679" xyz="0 0 0"/>
    <axis xyz="0 0 1"/>
    <!-- <limit effort="1.0" lower="-0.35" upper="1.92" velocity="1.0"/> -->
    <limit effort="1.0" lower="0.0" upper="1.5" velocity="1.0"/>
    <dynamics damping="1.0"/>
  </joint>
  <transmission name="tran3">
    <type>transmission_interface/SimpleTransmission</type>
    <joint name="joint3">
      <hardwareInterface>hardware_interface/EffortJointInterface</hardwareInterface>
    </joint>
    <actuator name="motor3">
      <hardwareInterface>hardware_interface/EffortJointInterface</hardwareInterface>
      <mechanicalReduction>1</mechanicalReduction>
    </actuator>
  </transmission>
  <!-- Link3 -->
  <link name="link3">
    <collision>
      <origin rpy="0 0 0" xyz="0 0 0"/>
      <geometry>
        <mesh filename="package://kinton_description/meshes/arm/link3.stl"/>
      </geometry>
      <contact_coefficients kd="1.0" kp="1000.0" mu="0"/>
    </collision>
    <visual>
      <origin rpy="0 0 0" xyz="0 0 0"/>
      <geometry>
        <mesh filename="package://kinton_description/meshes/arm/link3.dae"/>
      </geometry>
      <material name="white"/>
    </visual>
    <inertial>
      <origin rpy="0 0 0" xyz="0 0 0"/>
      <mass value="0.0002"/>
      <inertia ixx="0.01" ixy="0.0" ixz="0.0" iyy="0.01" iyz="0.0" izz="0.01"/>
    </inertial>
  </link>
  <joint name="joint4" type="revolute">
    <parent link="link3"/>
    <child link="link4"/>
    <origin rpy="0 0 -1.57079632679" xyz="0 -0.063 0"/>
    <axis xyz="0 0 1"/>
    <!-- <limit effort="1.0" lower="-2.35" upper="2.35" velocity="1.0"/> -->
    <limit effort="1.0" lower="-2.1" upper="2.1" velocity="1.0"/>
    <dynamics damping="1.0"/>
  </joint>
  <transmission name="tran4">
    <type>transmission_interface/SimpleTransmission</type>
    <joint name="joint4">
      <hardwareInterface>hardware_interface/EffortJointInterface</hardwareInterface>
    </joint>
    <actuator name="motor4">
      <hardwareInterface>hardware_interface/EffortJointInterface</hardwareInterface>
      <mechanicalReduction>1</mechanicalReduction>
    </actuator>
  </transmission>
  <!-- Link4 -->
  <link name="link4">
    <collision>
      <origin rpy="0 0 0" xyz="0 0 0"/>
      <geometry>
        <mesh filename="package://kinton_description/meshes/arm/link4.stl"/>
      </geometry>
      <contact_coefficients kd="1.0" kp="1000.0" mu="0"/>
    </collision>
    <visual>
      <origin rpy="0 0 0" xyz="0 0 0"/>
      <geometry>
        <mesh filename="package://kinton_description/meshes/arm/link4.dae"/>
      </geometry>
      <material name="white"/>
    </visual>
    <inertial>
      <origin rpy="0 0 0" xyz="0 0 0"/>
      <mass value="0.0002"/>
      <inertia ixx="0.01" ixy="0.0" ixz="0.0" iyy="0.01" iyz="0.0" izz="0.01"/>
    </inertial>
  </link>
  <joint name="joint5" type="revolute">
    <parent link="link4"/>
    <child link="link5"/>
    <origin rpy="0 0 0" xyz="0.063 0 0"/>
    <axis xyz="0 0 1"/>
    <limit effort="1.0" lower="-2.35" upper="2.35" velocity="1.0"/>
    <dynamics damping="1.0"/>
  </joint>
  <transmission name="tran5">
    <type>transmission_interface/SimpleTransmission</type>
    <joint name="joint5">
      <hardwareInterface>hardware_interface/EffortJointInterface</hardwareInterface>
    </joint>
    <actuator name="motor5">
      <hardwareInterface>hardware_interface/EffortJointInterface</hardwareInterface>
      <mechanicalReduction>1</mechanicalReduction>
    </actuator>
  </transmission>
  <!-- Link5 -->
  <link name="link5">
    <collision>
      <origin rpy="0 0 0" xyz="0 0 0"/>
      <geometry>
        <mesh filename="package://kinton_description/meshes/arm/link5.stl"/>
      </geometry>
      <contact_coefficients kd="1.0" kp="1000.0" mu="0"/>
    </collision>
    <visual>
      <origin rpy="0 0 0" xyz="0 0 0"/>
      <geometry>
        <mesh filename="package://kinton_description/meshes/arm/link5.dae"/>
      </geometry>
      <material name="white"/>
    </visual>
    <inertial>
      <origin rpy="0 0 0" xyz="0 0 0"/>
      <mass value="0.0002"/>
      <inertia ixx="0.01" ixy="0.0" ixz="0.0" iyy="0.01" iyz="0.0" izz="0.01"/>
    </inertial>
  </link>
  <joint name="joint6" type="revolute">
    <parent link="link5"/>
    <child link="link6"/>
    <origin rpy="1.57079632679 0 1.57079632679" xyz="0.0561 -0.0034 0"/>
    <axis xyz="0 0 1"/>
    <limit effort="1.0" lower="-2.094" upper="2.094" velocity="1.0"/>
    <dynamics damping="1.0"/>
  </joint>
  <transmission name="tran6">
    <type>transmission_interface/SimpleTransmission</type>
    <joint name="joint6">
      <hardwareInterface>hardware_interface/EffortJointInterface</hardwareInterface>
    </joint>
    <actuator name="motor6">
      <hardwareInterface>hardware_interface/EffortJointInterface</hardwareInterface>
      <mechanicalReduction>1</mechanicalReduction>
    </actuator>
  </transmission>
  <!-- Link6 -->
  <link name="link6">
    <collision>
      <origin rpy="0 0 0" xyz="0 0 0"/>
      <geometry>
        <mesh filename="package://kinton_description/meshes/arm/link6.stl"/>
      </geometry>
      <contact_coefficients kd="1.0" kp="1000.0" mu="0"/>
    </collision>
    <visual>
      <origin rpy="0 0 0" xyz="0 0 0"/>
      <geometry>
        <mesh filename="package://kinton_description/meshes/arm/link6.dae"/>
      </geometry>
      <material name="white"/>
    </visual>
    <inertial>
      <origin rpy="0 0 0" xyz="0 0 0"/>
      <mass value="0.0002"/>
      <inertia ixx="0.01" ixy="0.0" ixz="0.0" iyy="0.01" iyz="0.0" izz="0.01"/>
    </inertial>
  </link>
  <!-- ros_control plugin -->
  <gazebo>
    <plugin filename="libgazebo_ros_control.so" name="gazebo_ros_control">
      <robotNamespace>kinton</robotNamespace>
      <robotSimType>gazebo_ros_control/DefaultRobotHWSim</robotSimType>
    </plugin>
  </gazebo>
  <!-- Arm Base -->
  <gazebo reference="arm_base">
    <material>Gazebo/White</material>
    <selfCollide>true</selfCollide>
  </gazebo>
  <!-- Link1 -->
  <gazebo reference="link1">
    <mu1>0.2</mu1>
    <mu2>0.2</mu2>
    <material>Gazebo/White</material>
    <selfCollide>true</selfCollide>
  </gazebo>
  <!-- Link2 -->
  <gazebo reference="link2">
    <mu1>0.2</mu1>
    <mu2>0.2</mu2>
    <material>Gazebo/White</material>
    <selfCollide>true</selfCollide>
  </gazebo>
  <!-- Link3 -->
  <gazebo reference="link3">
    <mu1>0.2</mu1>
    <mu2>0.2</mu2>
    <material>Gazebo/White</material>
    <selfCollide>true</selfCollide>
  </gazebo>
  <!-- Link4 -->
  <gazebo reference="link4">
    <mu1>0.2</mu1>
    <mu2>0.2</mu2>
    <material>Gazebo/White</material>
    <selfCollide>true</selfCollide>
  </gazebo>
  <!-- Link5 -->
  <gazebo reference="link5">
    <mu1>0.2</mu1>
    <mu2>0.2</mu2>
    <material>Gazebo/White</material>
    <selfCollide>true</selfCollide>
  </gazebo>
  <!-- Link6 -->
  <gazebo reference="link6">
    <mu1>0.2</mu1>
    <mu2>0.2</mu2>
    <material>Gazebo/White</material>
    <selfCollide>false</selfCollide>
  </gazebo>
  <joint name="arm_cam_joint" type="fixed">
    <origin rpy="3.14159265359 -1.57079632679 0.0" xyz="0.0 0.0 0.01"/>
    <parent link="link6"/>
    <child link="arm_cam_link"/>
  </joint>
  <link name="arm_cam_link">
    <inertial>
      <mass value="0.0001"/>
      <origin rpy="0 0 0" xyz="0 0 0"/>
      <inertia ixx="0.0001" ixy="0" ixz="0" iyy="0.0001" iyz="0" izz="0.0001"/>
    </inertial>
    <visual>
      <origin rpy="0 1.57079632679 0" xyz="0 0 0"/>
      <geometry>
        <cylinder length="0.01" radius="0.005"/>
      </geometry>
      <material name="Blue">
        <color rgba="0.0 0.0 0.8 1"/>
      </material>
    </visual>
    <collision>
      <origin rpy="0 1.57079632679 0" xyz="0 0 0"/>
      <geometry>
        <cylinder length="0.01" radius="0.005"/>
      </geometry>
    </collision>
  </link>
  <joint name="arm_cam_optical_joint" type="fixed">
    <origin rpy="-1.57079632679 0 -1.57079632679" xyz="0.001 0 0"/>
    <parent link="arm_cam_link"/>
    <child link="arm_cam_optical_frame"/>
  </joint>
  <link name="arm_cam_optical_frame">
    <inertial>
      <mass value="0.0001"/>
      <origin rpy="0 0 0" xyz="0 0 0"/>
      <inertia ixx="0.001" ixy="0.0" ixz="0.0" iyy="0.001" iyz="0.0" izz="0.001"/>
    </inertial>
    <visual>
      <origin rpy="0 0 0" xyz="0 0 0"/>
      <geometry>
        <box size="0.001 0.001 0.001"/>
      </geometry>
    </visual>
    <collision>
      <origin rpy="0 0 0" xyz="0 0 0"/>
      <geometry>
        <box size="0.001 0.001 0.001"/>
      </geometry>
    </collision>
  </link>
  <gazebo reference="arm_cam_link">
    <sensor name="arm_cam_camera_sensor" type="camera">
      <update_rate>25</update_rate>
      <camera name="head">
        <horizontal_fov>1.5708</horizontal_fov>
        <image>
          <width>1280</width>
          <height>960</height>
          <format>R8G8B8</format>
        </image>
        <clip>
          <near>0.01</near>
          <far>100</far>
        </clip>
        <noise>
          <type>gaussian</type>
          <mean>0.0</mean>
          <stddev>0.000</stddev>
        </noise>
      </camera>
      <plugin filename="libgazebo_ros_camera.so" name="camera_plugin">
        <alwaysOn>true</alwaysOn>
        <updateRate>0.0</updateRate>
        <cameraName>kinton/arm_cam</cameraName>
        <imageTopicName>image_raw</imageTopicName>
        <cameraInfoTopicName>camera_info</cameraInfoTopicName>
        <frameName>kinton/arm_cam_optical_frame</frameName>
        <hackBaseline>0.07</hackBaseline>
        <distortionK1>0.0</distortionK1>
        <distortionK2>0.0</distortionK2>
        <distortionK3>0.0</distortionK3>
        <distortionT1>0.0</distortionT1>
        <distortionT2>0.0</distortionT2>
      </plugin>
    </sensor>
    <mu1>0.2</mu1>
    <mu2>0.2</mu2>
    <material>Gazebo/Black</material>
  </gazebo>
  <gazebo>
    <turnGravityOff>false</turnGravityOff>
    <static>false</static>
  </gazebo>
  <!--   <gazebo>
    <turnGravityOff>true</turnGravityOff>
    <static>true</static>      
    <plugin name="ground_truth" filename="libgazebo_ros_p3d.so">
      <frameName>world</frameName>
      <bodyName>${name}_optical_frame</bodyName>
      <topicName>${prefix}/${name}/odom</topicName>
      <updateRate>30.0</updateRate>
    </plugin>
  </gazebo>  
 -->
</robot>
